Workbook
Name LowMarginThreshold: Analysis!$C$96
Name SelYear: Dashboard!$D$5
Name Slicer_Channel: #N/A
Name Slicer_Has_Discount: #N/A

Sheet README
B2: Lumora Retail — Sales & Margin Analysis (Excel version)
B3: For business users: pick a year on the Dashboard and read the cards, charts and recommendations.
B5: PURPOSE
B6: Business question | C6: Gross margin fell from 27.4% (2017) to 25.0% (2022), then recovered to 27.6% (2025). What caused the dip, what drove the recovery, and what should we do next?
B7: Data source | C7: SYNTHETIC data for a fictional retailer (Lumora Retail), created in Python for a portfolio project. Not real company or customer data.
B8: Data size | C8: 565,969 cleaned order lines (about 262,000 completed orders, 2016–2025), aggregated to 6,160 rows: month × category × channel × discount flag. This keeps the file fast; every analysis in this workbook works at that level.
B10: SHEET GUIDE
B11: Dashboard | C11: One-screen summary. Choose a year in the yellow cell D5. KPI cards and the category chart follow the year; the margin trend and bridge always show the whole period.
B12: Data | C12: tblSales — the analysis table. Blue columns (E–I) are source values; Revenue, Gross Profit, Profit after Fees, Margin %, Year, Quarter and Month are formulas.
B13: Analysis | C13: All numbers as SUMIFS formulas on tblSales: margin by year, by category, by channel, with vs without discount, the margin bridge, marketplace fees, recommendation estimates, and checks against the Python results (all show OK).
B14: Top Products | C14: Top 20 products by 2025 revenue (used by recommendation R2).
B15: Power Query Steps | C15: M code to rebuild tblSales from the raw CSV files in Power Query.
B17: DEFINITIONS
B18: Revenue | C18: Gross sales (price × quantity) minus discounts. Completed orders only.
B19: Gross Profit | C19: Revenue minus cost of goods sold (COGS).
B20: Gross Margin % | C20: Gross Profit ÷ Revenue.
B21: Marketplace Fee | C21: Commission charged by the marketplace platform. It is NOT part of gross margin (this matches the Python analysis). It is shown separately as Profit after Fees and Margin after Fees %.
B22: Margin bridge | C22: Splits the change in gross margin into three drivers: supplier cost & pricing (cost relative to list price), product mix (selling more or less of high-margin categories) and discounts. The three drivers add up exactly to the change.
B24: COLOUR CODE
B25: Blue text | C25: Source data or assumptions typed in by hand.
B26: Yellow cell | C26: A value you can change (year selector, bridge years, recommendation assumptions).
B27: Black text | C27: Formulas — do not type over these.
B29: HOW TO UPDATE
B30: New data | C30: Paste new rows into tblSales columns A–I (or refresh the Power Query). The formula columns, Analysis, Dashboard and charts update automatically. If you add years after 2025, extend the year list in Analysis!A5:A14.

Sheet Dashboard
B2: Lumora Retail — Sales & Margin Dashboard
B3: Synthetic data for a fictional retailer · All amounts in Thai baht (฿) · Revenue = sales after discounts
B5: SELECT YEAR ▶ | D5: 2025 | F5: ◀ pick a year from the dropdown (2016–2025)
B7: REVENUE | E7: GROSS PROFIT | H7: GROSS MARGIN | K7: REVENUE GROWTH (YoY)
B8: =INDEX(Analysis!$D$5:$D$14,MATCH(SelYear,Analysis!$A$5:$A$14,0)) -> 92902055 | E8: =INDEX(Analysis!$F$5:$F$14,MATCH(SelYear,Analysis!$A$5:$A$14,0)) -> 25677751 | H8: =INDEX(Analysis!$G$5:$G$14,MATCH(SelYear,Analysis!$A$5:$A$14,0)) -> 0.27639595 | K8: =IF(SelYear=MIN(Analysis!$A$5:$A$14),"n/a",INDEX(Analysis!$L$5:$L$14,MATCH(SelYear,Analysis!$A$5:$A$14,0))) -> 0.12844065
B10: =IF(SelYear=MIN(Analysis!$A$5:$A$14),"n/a",INDEX(Analysis!$L$5:$L$14,MATCH(SelYear,Analysis!$A$5:$A$14,0))) -> 0.12844065 | E10: =IF(SelYear=MIN(Analysis!$A$5:$A$14),"n/a",INDEX(Analysis!$M$5:$M$14,MATCH(SelYear,Analysis!$A$5:$A$14,0))) -> 0.18498218 | H10: =IF(SelYear=MIN(Analysis!$A$5:$A$14),"n/a",INDEX(Analysis!$N$5:$N$14,MATCH(SelYear,Analysis!$A$5:$A$14,0))) -> 1.3188257 | K10: =IF(SelYear=MIN(Analysis!$A$5:$A$14),"n/a",INDEX(Analysis!$M$5:$M$14,MATCH(SelYear,Analysis!$A$5:$A$14,0))) -> 0.18498218
B11: =IF(SelYear=MIN(Analysis!$A$5:$A$14),"first year in the data","vs "&(SelYear-1)) -> vs 2024 | E11: =IF(SelYear=MIN(Analysis!$A$5:$A$14),"first year in the data","vs "&(SelYear-1)) -> vs 2024 | H11: =IF(SelYear=MIN(Analysis!$A$5:$A$14),"first year in the data","vs "&(SelYear-1)) -> vs 2024 | K11: ="gross profit growth" -> gross profit growth
B13: Gross margin by year | H13: ="Gross profit by category, "&SelYear -> Gross profit by category, 2025
B14: Dipped to a low in 2022, then recovered | H14: Electronics and Home Appliances sell the most but earn the least per baht
B32: ="What moved gross margin: "&Analysis!B47&" → "&Analysis!H47&" → "&Analysis!N47 -> What moved gross margin: 2017 → 2022 → 2025
B33: Green = raised margin, red = lowered margin, blue = margin level. Axis starts at 20% to show the steps.
J34: Recommendations
J35: Estimated extra gross profit per year (base: 2025)
J37: 1. Bring discounts back to the 2022 level | M37: =Analysis!C104 -> 1233482.5
J39: 2. Raise prices 3% on low-margin best sellers | M39: =Analysis!C105 -> 757425.03
J41: 3. Move 20% of marketplace sales to our app | M41: =Analysis!C106 -> 566756.57
J43: 4. Win back 10% of At Risk customers | M43: =Analysis!C107 -> 342770.19
J46: Total | M46: =Analysis!C108 -> 2900434.2
J48: Estimates assume sales volume stays the same. Assumptions: Analysis sheet, section 8.

Sheet Pivot
A1: Lumora Retail — Pivot
B3: Column Labels
B4: Beauty & Personal Care | D4: Electronics | F4: Fashion | H4: Grocery & FMCG | J4: Home & Living | L4: Home Appliances | N4: Sports & Outdoor | P4: Total Sum of Gross Profit | Q4: Total Sum of GM %
A5: Row Labels | B5: Sum of Gross Profit | C5: Sum of GM % | D5: Sum of Gross Profit | E5: Sum of GM % | F5: Sum of Gross Profit | G5: Sum of GM % | H5: Sum of Gross Profit | I5: Sum of GM % | J5: Sum of Gross Profit | K5: Sum of GM % | L5: Sum of Gross Profit | M5: Sum of GM % | N5: Sum of Gross Profit | O5: Sum of GM %
A6: 2016 | B6: 2055277.8 | C6: 0.39172144 | D6: 1520453.9 | E6: 0.11386675 | F6: 3348852.9 | G6: 0.53891418 | H6: 607595.19 | I6: 0.16124239 | J6: 2748337.8 | K6: 0.45263689 | L6: 2202779.1 | M6: 0.15398995 | N6: 2257547.7 | O6: 0.44346548 | P6: 14740845 | Q6: 0.27273002
A7: 2017 | B7: 2078930.9 | C7: 0.39373016 | D7: 1576784.5 | E7: 0.11888363 | F7: 3350209.7 | G7: 0.53929566 | H7: 585030.02 | I7: 0.15981968 | J7: 2709065.7 | K7: 0.45510413 | L7: 2171466.1 | M7: 0.15456198 | N7: 2158096.9 | O7: 0.44025943 | P7: 14629584 | Q7: 0.27437446
A8: 2018 | B8: 2210786.2 | C8: 0.38715261 | D8: 1686240.3 | E8: 0.1142567 | F8: 3559762.6 | G8: 0.53885855 | H8: 621122.94 | I8: 0.15972306 | J8: 2802144.6 | K8: 0.45389306 | L8: 2321500.7 | M8: 0.15307999 | N8: 2501612.4 | O8: 0.44388588 | P8: 15703170 | Q8: 0.27103329
A9: 2019 | B9: 2272685 | C9: 0.38787637 | D9: 1872116.7 | E9: 0.11558089 | F9: 3827865 | G9: 0.5395017 | H9: 660392.4 | I9: 0.15973459 | J9: 3030795.5 | K9: 0.45323083 | L9: 2431479.4 | M9: 0.1523959 | N9: 2513857.9 | O9: 0.44082973 | P9: 16609192 | Q9: 0.26949444
A10: 2020 | B10: 2437502.7 | C10: 0.38611178 | D10: 2163055.9 | E10: 0.11182951 | F10: 3876400.8 | G10: 0.53702583 | H10: 630038.4 | I10: 0.15890572 | J10: 3182424.8 | K10: 0.45279144 | L10: 2799345.8 | M10: 0.15118227 | N10: 2703156.2 | O10: 0.4426011 | P10: 17791925 | Q10: 0.25977111
A11: 2021 | B11: 2526628.8 | C11: 0.38426405 | D11: 2540293.4 | E11: 0.11515823 | F11: 4173649.9 | G11: 0.53935166 | H11: 650992.72 | I11: 0.15919256 | J11: 3412100.4 | K11: 0.45339685 | L11: 3111413.2 | M11: 0.15316966 | N11: 2870218.6 | O11: 0.44609993 | P11: 19285297 | Q11: 0.25804844
A12: 2022 | B12: 2806000.8 | C12: 0.38322988 | D12: 2700094.1 | E12: 0.10771956 | F12: 4607804.5 | G12: 0.53629225 | H12: 702189.6 | I12: 0.1544757 | J12: 3648802.9 | K12: 0.44910175 | L12: 3330260.8 | M12: 0.14529645 | N12: 3098491.8 | O12: 0.43642729 | P12: 20893644 | Q12: 0.24971389
A13: 2023 | B13: 2789844.2 | C13: 0.39058808 | D13: 3115355.2 | E13: 0.1194395 | F13: 4419678.5 | G13: 0.54280432 | H13: 738441.54 | I13: 0.16762258 | J13: 3631332.5 | K13: 0.45786653 | L13: 3617946.5 | M13: 0.15970307 | N13: 3081051.2 | O13: 0.44574495 | P13: 21393650 | Q13: 0.25691653
A14: 2024 | B14: 2770992.1 | C14: 0.39922769 | D14: 3336155.4 | E14: 0.12940391 | F14: 4395556.5 | G14: 0.54682121 | H14: 743962.9 | I14: 0.1749875 | J14: 3597639.1 | K14: 0.46164961 | L14: 3746190.6 | M14: 0.16532421 | N14: 3078817.8 | O14: 0.44858368 | P14: 21669314 | Q14: 0.26320769
A15: 2025 | B15: 3110671.6 | C15: 0.41242275 | D15: 4583874.2 | E15: 0.15073323 | F15: 4963060.1 | G15: 0.56142179 | H15: 894453.9 | I15: 0.19657643 | J15: 3985650.1 | K15: 0.47839588 | L15: 4838602.5 | M15: 0.18496859 | N15: 3301439 | O15: 0.46706619 | P15: 25677751 | Q15: 0.27639595
A16: Grand Total | B16: 25059320 | C16: 0.391964 | D16: 25094424 | E16: 0.12163211 | F16: 40522841 | G16: 0.5424967 | H16: 6834219.6 | I16: 0.16564302 | J16: 32748293 | K16: 0.45725597 | L16: 30570985 | M16: 0.15864763 | N16: 27564290 | O16: 0.4459087 | P16: 1.8839437e+08 | Q16: 0.26447438

Sheet Data
A1: Period | B1: Category | C1: Channel | D1: Has Discount | E1: Units | F1: Gross Sales | G1: Discount Amount | H1: COGS | I1: Marketplace Fee | J1: Revenue | K1: Gross Profit | L1: Profit after Fees | M1: Margin % | N1: Year | O1: Quarter | P1: Month
A2: 42370 | B2: Beauty & Personal Care | C2: Mobile App | D2: No | E2: 9 | F2: 3018 | G2: 0 | H2: 1969.73 | I2: 0 | J2: =F2-G2 -> 3018 | K2: =J2-H2 -> 1048.27 | L2: =K2-I2 -> 1048.27 | M2: =IF(J2=0,0,K2/J2) -> 0.3473393 | N2: =YEAR(A2) -> 2016 | O2: ="Q"&ROUNDUP(MONTH(A2)/3,0) -> Q1 | P2: =MONTH(A2) -> 1
A3: 42370 | B3: Beauty & Personal Care | C3: Mobile App | D3: Yes | E3: 1 | F3: 129 | G3: 12.9 | H3: 66.04 | I3: 0 | J3: =F3-G3 -> 116.1 | K3: =J3-H3 -> 50.06 | L3: =K3-I3 -> 50.06 | M3: =IF(J3=0,0,K3/J3) -> 0.43118002 | N3: =YEAR(A3) -> 2016 | O3: ="Q"&ROUNDUP(MONTH(A3)/3,0) -> Q1 | P3: =MONTH(A3) -> 1
A4: 42370 | B4: Beauty & Personal Care | C4: Store | D4: No | E4: 1149 | F4: 436154 | G4: 0 | H4: 260749.58 | I4: 0 | J4: =F4-G4 -> 436154 | K4: =J4-H4 -> 175404.42 | L4: =K4-I4 -> 175404.42 | M4: =IF(J4=0,0,K4/J4) -> 0.40216167 | N4: =YEAR(A4) -> 2016 | O4: ="Q"&ROUNDUP(MONTH(A4)/3,0) -> Q1 | P4: =MONTH(A4) -> 1
A5: 42370 | B5: Beauty & Personal Care | C5: Store | D5: Yes | E5: 165 | F5: 63834 | G5: 5012.85 | H5: 38530.61 | I5: 0 | J5: =F5-G5 -> 58821.15 | K5: =J5-H5 -> 20290.54 | L5: =K5-I5 -> 20290.54 | M5: =IF(J5=0,0,K5/J5) -> 0.34495313 | N5: =YEAR(A5) -> 2016 | O5: ="Q"&ROUNDUP(MONTH(A5)/3,0) -> Q1 | P5: =MONTH(A5) -> 1
A6: 42370 | B6: Beauty & Personal Care | C6: Website | D6: No | E6: 54 | F6: 20156 | G6: 0 | H6: 13012.1 | I6: 0 | J6: =F6-G6 -> 20156 | K6: =J6-H6 -> 7143.9 | L6: =K6-I6 -> 7143.9 | M6: =IF(J6=0,0,K6/J6) -> 0.35443044 | N6: =YEAR(A6) -> 2016 | O6: ="Q"&ROUNDUP(MONTH(A6)/3,0) -> Q1 | P6: =MONTH(A6) -> 1
A7: 42370 | B7: Beauty & Personal Care | C7: Website | D7: Yes | E7: 9 | F7: 3491 | G7: 258.8 | H7: 2240.46 | I7: 0 | J7: =F7-G7 -> 3232.2 | K7: =J7-H7 -> 991.74 | L7: =K7-I7 -> 991.74 | M7: =IF(J7=0,0,K7/J7) -> 0.30683126 | N7: =YEAR(A7) -> 2016 | O7: ="Q"&ROUNDUP(MONTH(A7)/3,0) -> Q1 | P7: =MONTH(A7) -> 1
A8: 42370 | B8: Electronics | C8: Mobile App | D8: No | E8: 4 | F8: 11866 | G8: 0 | H8: 10932.82 | I8: 0 | J8: =F8-G8 -> 11866 | K8: =J8-H8 -> 933.18 | L8: =K8-I8 -> 933.18 | M8: =IF(J8=0,0,K8/J8) -> 0.078643182 | N8: =YEAR(A8) -> 2016 | O8: ="Q"&ROUNDUP(MONTH(A8)/3,0) -> Q1 | P8: =MONTH(A8) -> 1
A9: 42370 | B9: Electronics | C9: Store | D9: No | E9: 235 | F9: 1182755 | G9: 0 | H9: 1034005.1 | I9: 0 | J9: =F9-G9 -> 1182755 | K9: =J9-H9 -> 148749.89 | L9: =K9-I9 -> 148749.89 | M9: =IF(J9=0,0,K9/J9) -> 0.1257656 | N9: =YEAR(A9) -> 2016 | O9: ="Q"&ROUNDUP(MONTH(A9)/3,0) -> Q1 | P9: =MONTH(A9) -> 1
A10: 42370 | B10: Electronics | C10: Store | D10: Yes | E10: 23 | F10: 145517 | G10: 12132.1 | H10: 123620.4 | I10: 0 | J10: =F10-G10 -> 133384.9 | K10: =J10-H10 -> 9764.5 | L10: =K10-I10 -> 9764.5 | M10: =IF(J10=0,0,K10/J10) -> 0.073205438 | N10: =YEAR(A10) -> 2016 | O10: ="Q"&ROUNDUP(MONTH(A10)/3,0) -> Q1 | P10: =MONTH(A10) -> 1
A11: 42370 | B11: Electronics | C11: Website | D11: No | E11: 11 | F11: 65009 | G11: 0 | H11: 57894.56 | I11: 0 | J11: =F11-G11 -> 65009 | K11: =J11-H11 -> 7114.44 | L11: =K11-I11 -> 7114.44 | M11: =IF(J11=0,0,K11/J11) -> 0.10943777 | N11: =YEAR(A11) -> 2016 | O11: ="Q"&ROUNDUP(MONTH(A11)/3,0) -> Q1 | P11: =MONTH(A11) -> 1
A12: 42370 | B12: Electronics | C12: Website | D12: Yes | E12: 6 | F12: 54104 | G12: 4020.95 | H12: 45928.89 | I12: 0 | J12: =F12-G12 -> 50083.05 | K12: =J12-H12 -> 4154.16 | L12: =K12-I12 -> 4154.16 | M12: =IF(J12=0,0,K12/J12) -> 0.082945428 | N12: =YEAR(A12) -> 2016 | O12: ="Q"&ROUNDUP(MONTH(A12)/3,0) -> Q1 | P12: =MONTH(A12) -> 1
A13: 42370 | B13: Fashion | C13: Mobile App | D13: No | E13: 10 | F13: 6090 | G13: 0 | H13: 2816.53 | I13: 0 | J13: =F13-G13 -> 6090 | K13: =J13-H13 -> 3273.47 | L13: =K13-I13 -> 3273.47 | M13: =IF(J13=0,0,K13/J13) -> 0.5375156 | N13: =YEAR(A13) -> 2016 | O13: ="Q"&ROUNDUP(MONTH(A13)/3,0) -> Q1 | P13: =MONTH(A13) -> 1
... A6161: 45992 | B6161: Sports & Outdoor | C6161: Website | D6161: Yes | E6161: 18 | F6161: 23402.32 | G6161: 4102.66 | H6161: 12389.83 | I6161: 0 | J6161: =F6161-G6161 -> 19299.66 | K6161: =J6161-H6161 -> 6909.83 | L6161: =K6161-I6161 -> 6909.83 | M6161: =IF(J6161=0,0,K6161/J6161) -> 0.35802859 | N6161: =YEAR(A6161) -> 2025 | O6161: ="Q"&ROUNDUP(MONTH(A6161)/3,0) -> Q4 | P6161: =MONTH(A6161) -> 12

Sheet Top Products
A1: Top 20 products by revenue, 2025
A2: Source: product-level totals for 2025 from the cleaned order lines (Python). Gross Profit, Margin % and the low-margin flag are formulas. Used by recommendation R2 on the Analysis sheet.
A4: Rank | B4: Product | C4: Category | D4: Revenue | E4: COGS | F4: Gross Profit | G4: Margin % | H4: Low Margin?
A5: 1 | B5: Lumora Home Air Fryer V83 | C5: Home Appliances | D5: 8754209.8 | E5: 8012284.4 | F5: =D5-E5 -> 741925.33 | G5: =IF(D5=0,0,F5/D5) -> 0.084750691 | H5: =IF(G5<LowMarginThreshold,"Yes","No") -> Yes
A6: 2 | B6: Pixelon Smartphone J88 | C6: Electronics | D6: 6121491.5 | E6: 5637646.4 | F6: =D6-E6 -> 483845.09 | G6: =IF(D6=0,0,F6/D6) -> 0.079040393 | H6: =IF(G6<LowMarginThreshold,"Yes","No") -> Yes
A7: 3 | B7: Nexora Laptop G10 | C7: Electronics | D7: 3006853.7 | E7: 2722743.6 | F7: =D7-E7 -> 284110.08 | G7: =IF(D7=0,0,F7/D7) -> 0.094487497 | H7: =IF(G7<LowMarginThreshold,"Yes","No") -> Yes
A8: 4 | B8: HomeBright Rice Cooker C34 | C8: Home Appliances | D8: 2828624.1 | E8: 2629665.5 | F8: =D8-E8 -> 198958.6 | G8: =IF(D8=0,0,F8/D8) -> 0.070337589 | H8: =IF(G8<LowMarginThreshold,"Yes","No") -> Yes
A9: 5 | B9: Lumora Tech Headphones Y31 | C9: Electronics | D9: 2665528.9 | E9: 2174235.2 | F9: =D9-E9 -> 491293.74 | G9: =IF(D9=0,0,F9/D9) -> 0.18431379 | H9: =IF(G9<LowMarginThreshold,"Yes","No") -> No
A10: 6 | B10: FitCore Yoga Mat H38 | C10: Sports & Outdoor | D10: 2061217.2 | E10: 855662.58 | F10: =D10-E10 -> 1205554.7 | G10: =IF(D10=0,0,F10/D10) -> 0.58487511 | H10: =IF(G10<LowMarginThreshold,"Yes","No") -> No
A11: 7 | B11: HomeBright Air Purifier T37 | C11: Home Appliances | D11: 2022466 | E11: 1357685.9 | F11: =D11-E11 -> 664780.02 | G11: =IF(D11=0,0,F11/D11) -> 0.32869775 | H11: =IF(G11<LowMarginThreshold,"Yes","No") -> No
A12: 8 | B12: StrideOn T-Shirt N33 | C12: Fashion | D12: 1355593.9 | E12: 718927.68 | F12: =D12-E12 -> 636666.26 | G12: =IF(D12=0,0,F12/D12) -> 0.46965853 | H12: =IF(G12<LowMarginThreshold,"Yes","No") -> No
A13: 9 | B13: Lumora Beauty Sunscreen Y72 | C13: Beauty & Personal Care | D13: 1316921.3 | E13: 1207121.4 | F13: =D13-E13 -> 109799.85 | G13: =IF(D13=0,0,F13/D13) -> 0.083376167 | H13: =IF(G13<LowMarginThreshold,"Yes","No") -> Yes
A14: 10 | B14: SonicPeak Laptop K10 | C14: Electronics | D14: 1247383.8 | E14: 1082314.5 | F14: =D14-E14 -> 165069.25 | G14: =IF(D14=0,0,F14/D14) -> 0.13233237 | H14: =IF(G14<LowMarginThreshold,"Yes","No") -> No
A15: 11 | B15: AeroLife Electric Fan I53 | C15: Home Appliances | D15: 1197760.9 | E15: 1117815.2 | F15: =D15-E15 -> 79945.64 | G15: =IF(D15=0,0,F15/D15) -> 0.066745911 | H15: =IF(G15<LowMarginThreshold,"Yes","No") -> Yes
A16: 12 | B16: CasaNest Bedding I91 | C16: Home & Living | D16: 1111911.7 | E16: 588033.86 | F16: =D16-E16 -> 523877.88 | G16: =IF(D16=0,0,F16/D16) -> 0.4711506 | H16: =IF(G16<LowMarginThreshold,"Yes","No") -> No
... A24: 20 | B24: HomeBright Microwave L83 | C24: Home Appliances | D24: 717618.24 | E24: 490869.25 | F24: =D24-E24 -> 226748.99 | G24: =IF(D24=0,0,F24/D24) -> 0.3159744 | H24: =IF(G24<LowMarginThreshold,"Yes","No") -> No

Sheet Analysis
A1: Analysis — every number is a formula on tblSales
A2: ="Selected year (from the Dashboard): "&SelYear -> Selected year (from the Dashboard): 2025
A3: 1. Sales and margin by year | P3: Check vs Python results
A4: Year | B4: Gross Sales | C4: Discount | D4: Revenue | E4: COGS | F4: Gross Profit | G4: Gross Margin % | H4: Discount Rate | I4: Marketplace Fee | J4: Profit after Fees | K4: Margin after Fees % | L4: Revenue YoY | M4: Gross Profit YoY | N4: Margin change (pts) | P4: Year | Q4: Excel | R4: Python | S4: Status
A5: 2016 | B5: =SUMIFS(tblSales[Gross Sales],tblSales[Year],$A5) -> 54893815 | C5: =SUMIFS(tblSales[Discount Amount],tblSales[Year],$A5) -> 844595.46 | D5: =SUMIFS(tblSales[Revenue],tblSales[Year],$A5) -> 54049220 | E5: =SUMIFS(tblSales[COGS],tblSales[Year],$A5) -> 39308375 | F5: =D5-E5 -> 14740845 | G5: =IF(D5=0,0,F5/D5) -> 0.27273002 | H5: =IF(B5=0,0,C5/B5) -> 0.015385986 | I5: =SUMIFS(tblSales[Marketplace Fee],tblSales[Year],$A5) -> 0 | J5: =F5-I5 -> 14740845 | K5: =IF(D5=0,0,J5/D5) -> 0.27273002 | L5: ="n/a" -> n/a | M5: ="n/a" -> n/a | N5: ="n/a" -> n/a | P5: 2017 | Q5: =INDEX($G$5:$G$14,MATCH(P5,$A$5:$A$14,0)) -> 0.27437446 | R5: 0.274 | S5: =IF(ABS(Q5-R5)<0.0005,"OK - matches","CHECK") -> OK - matches
A6: 2017 | B6: =SUMIFS(tblSales[Gross Sales],tblSales[Year],$A6) -> 54232139 | C6: =SUMIFS(tblSales[Discount Amount],tblSales[Year],$A6) -> 912366.36 | D6: =SUMIFS(tblSales[Revenue],tblSales[Year],$A6) -> 53319773 | E6: =SUMIFS(tblSales[COGS],tblSales[Year],$A6) -> 38690189 | F6: =D6-E6 -> 14629584 | G6: =IF(D6=0,0,F6/D6) -> 0.27437446 | H6: =IF(B6=0,0,C6/B6) -> 0.016823352 | I6: =SUMIFS(tblSales[Marketplace Fee],tblSales[Year],$A6) -> 0 | J6: =F6-I6 -> 14629584 | K6: =IF(D6=0,0,J6/D6) -> 0.27437446 | L6: =IF(D5=0,0,D6/D5-1) -> -0.01349597 | M6: =IF(F5=0,0,F6/F5-1) -> -0.0075477826 | N6: =(G6-G5)*100 -> 0.16444425 | P6: 2022 | Q6: =INDEX($G$5:$G$14,MATCH(P6,$A$5:$A$14,0)) -> 0.24971389 | R6: 0.25 | S6: =IF(ABS(Q6-R6)<0.0005,"OK - matches","CHECK") -> OK - matches
A7: 2018 | B7: =SUMIFS(tblSales[Gross Sales],tblSales[Year],$A7) -> 58950390 | C7: =SUMIFS(tblSales[Discount Amount],tblSales[Year],$A7) -> 1012231.8 | D7: =SUMIFS(tblSales[Revenue],tblSales[Year],$A7) -> 57938158 | E7: =SUMIFS(tblSales[COGS],tblSales[Year],$A7) -> 42234988 | F7: =D7-E7 -> 15703170 | G7: =IF(D7=0,0,F7/D7) -> 0.27103329 | H7: =IF(B7=0,0,C7/B7) -> 0.01717091 | I7: =SUMIFS(tblSales[Marketplace Fee],tblSales[Year],$A7) -> 34342.33 | J7: =F7-I7 -> 15668827 | K7: =IF(D7=0,0,J7/D7) -> 0.27044055 | L7: =IF(D6=0,0,D7/D6-1) -> 0.086616741 | M7: =IF(F6=0,0,F7/F6-1) -> 0.073384585 | N7: =(G7-G6)*100 -> -0.33411648 | P7: 2025 | Q7: =INDEX($G$5:$G$14,MATCH(P7,$A$5:$A$14,0)) -> 0.27639595 | R7: 0.276 | S7: =IF(ABS(Q7-R7)<0.0005,"OK - matches","CHECK") -> OK - matches
A8: 2019 | B8: =SUMIFS(tblSales[Gross Sales],tblSales[Year],$A8) -> 62790928 | C8: =SUMIFS(tblSales[Discount Amount],tblSales[Year],$A8) -> 1160001.9 | D8: =SUMIFS(tblSales[Revenue],tblSales[Year],$A8) -> 61630926 | E8: =SUMIFS(tblSales[COGS],tblSales[Year],$A8) -> 45021735 | F8: =D8-E8 -> 16609192 | G8: =IF(D8=0,0,F8/D8) -> 0.26949444 | H8: =IF(B8=0,0,C8/B8) -> 0.018474037 | I8: =SUMIFS(tblSales[Marketplace Fee],tblSales[Year],$A8) -> 105177.04 | J8: =F8-I8 -> 16504015 | K8: =IF(D8=0,0,J8/D8) -> 0.26778788 | L8: =IF(D7=0,0,D8/D7-1) -> 0.063736383 | M8: =IF(F7=0,0,F8/F7-1) -> 0.057696769 | N8: =(G8-G7)*100 -> -0.15388553 | P8: Python values are rounded to 0.1%, so a match means within 0.05 pts.
A9: 2020 | B9: =SUMIFS(tblSales[Gross Sales],tblSales[Year],$A9) -> 69864841 | C9: =SUMIFS(tblSales[Discount Amount],tblSales[Year],$A9) -> 1374067.5 | D9: =SUMIFS(tblSales[Revenue],tblSales[Year],$A9) -> 68490774 | E9: =SUMIFS(tblSales[COGS],tblSales[Year],$A9) -> 50698849 | F9: =D9-E9 -> 17791925 | G9: =IF(D9=0,0,F9/D9) -> 0.25977111 | H9: =IF(B9=0,0,C9/B9) -> 0.019667511 | I9: =SUMIFS(tblSales[Marketplace Fee],tblSales[Year],$A9) -> 408728.59 | J9: =F9-I9 -> 17383196 | K9: =IF(D9=0,0,J9/D9) -> 0.25380347 | L9: =IF(D8=0,0,D9/D8-1) -> 0.11130527 | M9: =IF(F8=0,0,F9/F8-1) -> 0.071209524 | N9: =(G9-G8)*100 -> -0.9723324
A10: 2021 | B10: =SUMIFS(tblSales[Gross Sales],tblSales[Year],$A10) -> 76143990 | C10: =SUMIFS(tblSales[Discount Amount],tblSales[Year],$A10) -> 1408808.4 | D10: =SUMIFS(tblSales[Revenue],tblSales[Year],$A10) -> 74735182 | E10: =SUMIFS(tblSales[COGS],tblSales[Year],$A10) -> 55449885 | F10: =D10-E10 -> 19285297 | G10: =IF(D10=0,0,F10/D10) -> 0.25804844 | H10: =IF(B10=0,0,C10/B10) -> 0.018501899 | I10: =SUMIFS(tblSales[Marketplace Fee],tblSales[Year],$A10) -> 804847.91 | J10: =F10-I10 -> 18480449 | K10: =IF(D10=0,0,J10/D10) -> 0.24727911 | L10: =IF(D9=0,0,D10/D9-1) -> 0.091171527 | M10: =IF(F9=0,0,F10/F9-1) -> 0.08393541 | N10: =(G10-G9)*100 -> -0.17226752
A11: 2022 | B11: =SUMIFS(tblSales[Gross Sales],tblSales[Year],$A11) -> 85607578 | C11: =SUMIFS(tblSales[Discount Amount],tblSales[Year],$A11) -> 1937244.8 | D11: =SUMIFS(tblSales[Revenue],tblSales[Year],$A11) -> 83670333 | E11: =SUMIFS(tblSales[COGS],tblSales[Year],$A11) -> 62776688 | F11: =D11-E11 -> 20893644 | G11: =IF(D11=0,0,F11/D11) -> 0.24971389 | H11: =IF(B11=0,0,C11/B11) -> 0.022629361 | I11: =SUMIFS(tblSales[Marketplace Fee],tblSales[Year],$A11) -> 1053432.6 | J11: =F11-I11 -> 19840212 | K11: =IF(D11=0,0,J11/D11) -> 0.23712362 | L11: =IF(D10=0,0,D11/D10-1) -> 0.11955749 | M11: =IF(F10=0,0,F11/F10-1) -> 0.083397594 | N11: =(G11-G10)*100 -> -0.83345474
A12: 2023 | B12: =SUMIFS(tblSales[Gross Sales],tblSales[Year],$A12) -> 85643885 | C12: =SUMIFS(tblSales[Discount Amount],tblSales[Year],$A12) -> 2373067.5 | D12: =SUMIFS(tblSales[Revenue],tblSales[Year],$A12) -> 83270818 | E12: =SUMIFS(tblSales[COGS],tblSales[Year],$A12) -> 61877168 | F12: =D12-E12 -> 21393650 | G12: =IF(D12=0,0,F12/D12) -> 0.25691653 | H12: =IF(B12=0,0,C12/B12) -> 0.027708546 | I12: =SUMIFS(tblSales[Marketplace Fee],tblSales[Year],$A12) -> 1520151.3 | J12: =F12-I12 -> 19873498 | K12: =IF(D12=0,0,J12/D12) -> 0.23866102 | L12: =IF(D11=0,0,D12/D11-1) -> -0.0047748745 | M12: =IF(F11=0,0,F12/F11-1) -> 0.023930973 | N12: =(G12-G11)*100 -> 0.72026406
A13: 2024 | B13: =SUMIFS(tblSales[Gross Sales],tblSales[Year],$A13) -> 84829730 | C13: =SUMIFS(tblSales[Discount Amount],tblSales[Year],$A13) -> 2501914.2 | D13: =SUMIFS(tblSales[Revenue],tblSales[Year],$A13) -> 82327816 | E13: =SUMIFS(tblSales[COGS],tblSales[Year],$A13) -> 60658502 | F13: =D13-E13 -> 21669314 | G13: =IF(D13=0,0,F13/D13) -> 0.26320769 | H13: =IF(B13=0,0,C13/B13) -> 0.029493365 | I13: =SUMIFS(tblSales[Marketplace Fee],tblSales[Year],$A13) -> 1905676.8 | J13: =F13-I13 -> 19763638 | K13: =IF(D13=0,0,J13/D13) -> 0.24006027 | L13: =IF(D12=0,0,D13/D12-1) -> -0.011324512 | M13: =IF(F12=0,0,F13/F12-1) -> 0.012885349 | N13: =(G13-G12)*100 -> 0.6291158
A14: 2025 | B14: =SUMIFS(tblSales[Gross Sales],tblSales[Year],$A14) -> 96315086 | C14: =SUMIFS(tblSales[Discount Amount],tblSales[Year],$A14) -> 3413031.3 | D14: =SUMIFS(tblSales[Revenue],tblSales[Year],$A14) -> 92902055 | E14: =SUMIFS(tblSales[COGS],tblSales[Year],$A14) -> 67224303 | F14: =D14-E14 -> 25677751 | G14: =IF(D14=0,0,F14/D14) -> 0.27639595 | H14: =IF(B14=0,0,C14/B14) -> 0.035436103 | I14: =SUMIFS(tblSales[Marketplace Fee],tblSales[Year],$A14) -> 2833782.8 | J14: =F14-I14 -> 22843969 | K14: =IF(D14=0,0,J14/D14) -> 0.24589304 | L14: =IF(D13=0,0,D14/D13-1) -> 0.12844065 | M14: =IF(F13=0,0,F14/F13-1) -> 0.18498218 | N14: =(G14-G13)*100 -> 1.3188257
A17: 2. Revenue, gross profit and margin by category
A18: Category | B18: Revenue (all years) | C18: Gross Profit (all years) | D18: Margin % (all years) | E18: Share of Revenue (all years) | F18: Revenue (selected year) | G18: Gross Profit (selected year) | H18: Margin % (selected year) | I18: Share of Revenue (selected year)
A19: Electronics | B19: =SUMIFS(tblSales[Revenue],tblSales[Category],$A19) -> 2.0631413e+08 | C19: =SUMIFS(tblSales[Gross Profit],tblSales[Category],$A19) -> 25094424 | D19: =IF(B19=0,0,C19/B19) -> 0.12163211 | E19: =IF($B$26=0,0,B19/$B$26) -> 0.28963074 | F19: =SUMIFS(tblSales[Revenue],tblSales[Category],$A19,tblSales[Year],SelYear) -> 30410508 | G19: =SUMIFS(tblSales[Gross Profit],tblSales[Category],$A19,tblSales[Year],SelYear) -> 4583874.2 | H19: =IF(F19=0,0,G19/F19) -> 0.15073323 | I19: =IF($F$26=0,0,F19/$F$26) -> 0.32733945
A20: Home Appliances | B20: =SUMIFS(tblSales[Revenue],tblSales[Category],$A20) -> 1.926974e+08 | C20: =SUMIFS(tblSales[Gross Profit],tblSales[Category],$A20) -> 30570985 | D20: =IF(B20=0,0,C20/B20) -> 0.15864763 | E20: =IF($B$26=0,0,B20/$B$26) -> 0.27051511 | F20: =SUMIFS(tblSales[Revenue],tblSales[Category],$A20,tblSales[Year],SelYear) -> 26159050 | G20: =SUMIFS(tblSales[Gross Profit],tblSales[Category],$A20,tblSales[Year],SelYear) -> 4838602.5 | H20: =IF(F20=0,0,G20/F20) -> 0.18496859 | I20: =IF($F$26=0,0,F20/$F$26) -> 0.28157666
A21: Fashion | B21: =SUMIFS(tblSales[Revenue],tblSales[Category],$A21) -> 74696934 | C21: =SUMIFS(tblSales[Gross Profit],tblSales[Category],$A21) -> 40522841 | D21: =IF(B21=0,0,C21/B21) -> 0.5424967 | E21: =IF($B$26=0,0,B21/$B$26) -> 0.10486208 | F21: =SUMIFS(tblSales[Revenue],tblSales[Category],$A21,tblSales[Year],SelYear) -> 8840162.9 | G21: =SUMIFS(tblSales[Gross Profit],tblSales[Category],$A21,tblSales[Year],SelYear) -> 4963060.1 | H21: =IF(F21=0,0,G21/F21) -> 0.56142179 | I21: =IF($F$26=0,0,F21/$F$26) -> 0.095155731
A22: Home & Living | B22: =SUMIFS(tblSales[Revenue],tblSales[Category],$A22) -> 71619170 | C22: =SUMIFS(tblSales[Gross Profit],tblSales[Category],$A22) -> 32748293 | D22: =IF(B22=0,0,C22/B22) -> 0.45725597 | E22: =IF($B$26=0,0,B22/$B$26) -> 0.10054141 | F22: =SUMIFS(tblSales[Revenue],tblSales[Category],$A22,tblSales[Year],SelYear) -> 8331280.1 | G22: =SUMIFS(tblSales[Gross Profit],tblSales[Category],$A22,tblSales[Year],SelYear) -> 3985650.1 | H22: =IF(F22=0,0,G22/F22) -> 0.47839588 | I22: =IF($F$26=0,0,F22/$F$26) -> 0.089678104
A23: Beauty & Personal Care | B23: =SUMIFS(tblSales[Revenue],tblSales[Category],$A23) -> 63932709 | C23: =SUMIFS(tblSales[Gross Profit],tblSales[Category],$A23) -> 25059320 | D23: =IF(B23=0,0,C23/B23) -> 0.391964 | E23: =IF($B$26=0,0,B23/$B$26) -> 0.089750895 | F23: =SUMIFS(tblSales[Revenue],tblSales[Category],$A23,tblSales[Year],SelYear) -> 7542434.6 | G23: =SUMIFS(tblSales[Gross Profit],tblSales[Category],$A23,tblSales[Year],SelYear) -> 3110671.6 | H23: =IF(F23=0,0,G23/F23) -> 0.41242275 | I23: =IF($F$26=0,0,F23/$F$26) -> 0.081186951
A24: Sports & Outdoor | B24: =SUMIFS(tblSales[Revenue],tblSales[Category],$A24) -> 61815994 | C24: =SUMIFS(tblSales[Gross Profit],tblSales[Category],$A24) -> 27564290 | D24: =IF(B24=0,0,C24/B24) -> 0.4459087 | E24: =IF($B$26=0,0,B24/$B$26) -> 0.086779379 | F24: =SUMIFS(tblSales[Revenue],tblSales[Category],$A24,tblSales[Year],SelYear) -> 7068460.8 | G24: =SUMIFS(tblSales[Gross Profit],tblSales[Category],$A24,tblSales[Year],SelYear) -> 3301439 | H24: =IF(F24=0,0,G24/F24) -> 0.46706619 | I24: =IF($F$26=0,0,F24/$F$26) -> 0.076085086
A25: Grocery & FMCG | B25: =SUMIFS(tblSales[Revenue],tblSales[Category],$A25) -> 41258723 | C25: =SUMIFS(tblSales[Gross Profit],tblSales[Category],$A25) -> 6834219.6 | D25: =IF(B25=0,0,C25/B25) -> 0.16564302 | E25: =IF($B$26=0,0,B25/$B$26) -> 0.057920389 | F25: =SUMIFS(tblSales[Revenue],tblSales[Category],$A25,tblSales[Year],SelYear) -> 4550158.4 | G25: =SUMIFS(tblSales[Gross Profit],tblSales[Category],$A25,tblSales[Year],SelYear) -> 894453.9 | H25: =IF(F25=0,0,G25/F25) -> 0.19657643 | I25: =IF($F$26=0,0,F25/$F$26) -> 0.048978017
A26: Total | B26: =SUM(B19:B25) -> 7.1233505e+08 | C26: =SUM(C19:C25) -> 1.8839437e+08 | D26: =IF(B26=0,0,C26/B26) -> 0.26447438 | E26: =SUM(E19:E25) -> 1 | F26: =SUM(F19:F25) -> 92902055 | G26: =SUM(G19:G25) -> 25677751 | H26: =IF(F26=0,0,G26/F26) -> 0.27639595 | I26: =SUM(I19:I25) -> 1
A29: 3. Margin by channel
A30: Channel | B30: Revenue (selected year) | C30: Gross Profit (selected year) | D30: Margin % (selected year) | E30: Marketplace Fee (selected year) | F30: Margin after Fees % (selected year) | G30: Revenue (all years) | H30: Margin % (all years) | I30: Margin after Fees % (all years)
A31: Store | B31: =SUMIFS(tblSales[Revenue],tblSales[Channel],$A31,tblSales[Year],SelYear) -> 40176169 | C31: =SUMIFS(tblSales[Gross Profit],tblSales[Channel],$A31,tblSales[Year],SelYear) -> 12453068 | D31: =IF(B31=0,0,C31/B31) -> 0.30996156 | E31: =SUMIFS(tblSales[Marketplace Fee],tblSales[Channel],$A31,tblSales[Year],SelYear) -> 0 | F31: =IF(B31=0,0,(C31-E31)/B31) -> 0.30996156 | G31: =SUMIFS(tblSales[Revenue],tblSales[Channel],$A31) -> 4.4716552e+08 | H31: =IF(G31=0,0,SUMIFS(tblSales[Gross Profit],tblSales[Channel],$A31)/G31) -> 0.28012759 | I31: =IF(G31=0,0,SUMIFS(tblSales[Profit after Fees],tblSales[Channel],$A31)/G31) -> 0.28012759
A32: Marketplace | B32: =SUMIFS(tblSales[Revenue],tblSales[Channel],$A32,tblSales[Year],SelYear) -> 24616256 | C32: =SUMIFS(tblSales[Gross Profit],tblSales[Channel],$A32,tblSales[Year],SelYear) -> 6201061.9 | D32: =IF(B32=0,0,C32/B32) -> 0.25190922 | E32: =SUMIFS(tblSales[Marketplace Fee],tblSales[Channel],$A32,tblSales[Year],SelYear) -> 2833782.8 | F32: =IF(B32=0,0,(C32-E32)/B32) -> 0.13679087 | G32: =SUMIFS(tblSales[Revenue],tblSales[Channel],$A32) -> 94628548 | H32: =IF(G32=0,0,SUMIFS(tblSales[Gross Profit],tblSales[Channel],$A32)/G32) -> 0.23753132 | I32: =IF(G32=0,0,SUMIFS(tblSales[Profit after Fees],tblSales[Channel],$A32)/G32) -> 0.14595072
A33: Mobile App | B33: =SUMIFS(tblSales[Revenue],tblSales[Channel],$A33,tblSales[Year],SelYear) -> 21286939 | C33: =SUMIFS(tblSales[Gross Profit],tblSales[Channel],$A33,tblSales[Year],SelYear) -> 5308934.4 | D33: =IF(B33=0,0,C33/B33) -> 0.24939868 | E33: =SUMIFS(tblSales[Marketplace Fee],tblSales[Channel],$A33,tblSales[Year],SelYear) -> 0 | F33: =IF(B33=0,0,(C33-E33)/B33) -> 0.24939868 | G33: =SUMIFS(tblSales[Revenue],tblSales[Channel],$A33) -> 1.0334133e+08 | H33: =IF(G33=0,0,SUMIFS(tblSales[Gross Profit],tblSales[Channel],$A33)/G33) -> 0.23732879 | I33: =IF(G33=0,0,SUMIFS(tblSales[Profit after Fees],tblSales[Channel],$A33)/G33) -> 0.23732879
A34: Website | B34: =SUMIFS(tblSales[Revenue],tblSales[Channel],$A34,tblSales[Year],SelYear) -> 6822691.2 | C34: =SUMIFS(tblSales[Gross Profit],tblSales[Channel],$A34,tblSales[Year],SelYear) -> 1714687.3 | D34: =IF(B34=0,0,C34/B34) -> 0.25132125 | E34: =SUMIFS(tblSales[Marketplace Fee],tblSales[Channel],$A34,tblSales[Year],SelYear) -> 0 | F34: =IF(B34=0,0,(C34-E34)/B34) -> 0.25132125 | G34: =SUMIFS(tblSales[Revenue],tblSales[Channel],$A34) -> 67199649 | H34: =IF(G34=0,0,SUMIFS(tblSales[Gross Profit],tblSales[Channel],$A34)/G34) -> 0.2399991 | I34: =IF(G34=0,0,SUMIFS(tblSales[Profit after Fees],tblSales[Channel],$A34)/G34) -> 0.2399991
A35: Total | B35: =SUM(B31:B34) -> 92902055 | C35: =SUM(C31:C34) -> 25677751 | D35: =IF(B35=0,0,C35/B35) -> 0.27639595 | E35: =SUM(E31:E34) -> 2833782.8 | F35: =IF(B35=0,0,(C35-E35)/B35) -> 0.24589304 | G35: =SUM(G31:G34) -> 7.1233505e+08 | H35: =IF(G35=0,0,SUM(tblSales[Gross Profit])/G35) -> 0.26447438 | I35: =IF(G35=0,0,SUM(tblSales[Profit after Fees])/G35) -> 0.25230856
A38: 4. Margin with discount vs without discount
A39: Has Discount | B39: Revenue (all years) | C39: Gross Profit (all years) | D39: Margin % (all years) | E39: Share of Revenue (all years) | F39: Revenue (selected year) | G39: Gross Profit (selected year) | H39: Margin % (selected year) | I39: Share of Revenue (selected year)
A40: Yes | B40: =SUMIFS(tblSales[Revenue],tblSales[Has Discount],$A40) -> 1.394416e+08 | C40: =SUMIFS(tblSales[Gross Profit],tblSales[Has Discount],$A40) -> 26519112 | D40: =IF(B40=0,0,C40/B40) -> 0.19018077 | E40: =IF($B$42=0,0,B40/$B$42) -> 0.19575283 | F40: =SUMIFS(tblSales[Revenue],tblSales[Has Discount],$A40,tblSales[Year],SelYear) -> 24574711 | G40: =SUMIFS(tblSales[Gross Profit],tblSales[Has Discount],$A40,tblSales[Year],SelYear) -> 4820471.1 | H40: =IF(F40=0,0,G40/F40) -> 0.19615576 | I40: =IF($F$42=0,0,F40/$F$42) -> 0.26452279
A41: No | B41: =SUMIFS(tblSales[Revenue],tblSales[Has Discount],$A41) -> 5.7289345e+08 | C41: =SUMIFS(tblSales[Gross Profit],tblSales[Has Discount],$A41) -> 1.6187526e+08 | D41: =IF(B41=0,0,C41/B41) -> 0.28255736 | E41: =IF($B$42=0,0,B41/$B$42) -> 0.80424717 | F41: =SUMIFS(tblSales[Revenue],tblSales[Has Discount],$A41,tblSales[Year],SelYear) -> 68327344 | G41: =SUMIFS(tblSales[Gross Profit],tblSales[Has Discount],$A41,tblSales[Year],SelYear) -> 20857280 | H41: =IF(F41=0,0,G41/F41) -> 0.30525525 | I41: =IF($F$42=0,0,F41/$F$42) -> 0.73547721
A42: Total | B42: =SUM(B40:B41) -> 7.1233505e+08 | C42: =SUM(C40:C41) -> 1.8839437e+08 | D42: =IF(B42=0,0,C42/B42) -> 0.26447438 | E42: =SUM(E40:E41) -> 1 | F42: =SUM(F40:F41) -> 92902055 | G42: =SUM(G40:G41) -> 25677751 | H42: =IF(F42=0,0,G42/F42) -> 0.27639595 | I42: =SUM(I40:I41) -> 1
A43: "Has Discount" = the order line had any discount (promotion or member coupon).
A45: 5. Margin bridge — working table by category
A46: Gross margin = Σ (category share of revenue × category margin). Change is split into: product mix (shares moved), supplier cost & pricing (cost ÷ list price moved), discounts (discount rate moved).
B47: 2017 | H47: 2022 | N47: 2025
...

Sheet Power Query Steps
A1: Power Query (M) code — rebuild tblSales from the raw CSV files
A3: How to use: Data ▸ Get Data ▸ From Other Sources ▸ Blank Query ▸ Advanced Editor. Create 4 queries with the names shown
A4: (Orders, OrderItems, Products, Sales), paste each block, and change the folder path in each Source step to where your raw CSV files are.
A5: Load only 'Sales' to a worksheet (the other three: Close & Load To ▸ Only Create Connection). Then copy its columns A–I into tblSales.
A6: Lines starting with // are comments that explain each step.
A8: // ==================== QUERY 1: Orders ====================
A9: // Loads orders.csv and fixes the dirty columns. Works in Excel 2016 and later.
A10: let
A11: // 1. Read the raw file (change the folder path to yours)
A12: Source = Csv.Document(File.Contents("C:\LumoraData\raw\orders.csv"), [Delimiter = ",", Encoding = 65001, QuoteStyle = QuoteStyle.Csv]),
A13: // 2. Use the first row as column names
A14: Promoted = Table.PromoteHeaders(Source, [PromoteAllScalars = true]),
... A109: Sorted
